<?xml version="1.0" ?>
<!-- =================================================================================== -->
<!-- |    This document was autogenerated by xacro from indy7.xacro                    | -->
<!-- |    EDITING THIS FILE BY HAND IS NOT RECOMMENDED                                 | -->
<!-- =================================================================================== -->
<robot name="indy7_allegro_hand_right">
  <material name="black">
    <color rgba="0.0 0.0 0.0 1.0"/>
  </material>
  <material name="blue">
    <color rgba="0.0 0.0 0.8 1.0"/>
  </material>
  <material name="green">
    <color rgba="0.0 0.8 0.0 1.0"/>
  </material>
  <material name="grey_">
    <color rgba="0.2 0.2 0.2 1.0"/>
  </material>
  <material name="orange">
    <color rgba="1.0 0.4235294117647059 0.0392156862745098 1.0"/>
  </material>
  <material name="brown">
    <color rgba="0.8705882352941177 0.8117647058823529 0.7647058823529411 1.0"/>
  </material>
  <material name="red">
    <color rgba="0.8 0.0 0.0 1.0"/>
  </material>
  <material name="white">
    <color rgba="1.0 1.0 1.0 1.0"/>
  </material>
  <material name="metal">
    <color rgba="0.768627450980392 0.749019607843137 0.729411764705882 1"/>
  </material>
  <material name="metal_grey">
    <color rgba="0.501960784313725 0.501960784313725 0.501960784313725 1"/>
  </material>
  <material name="metal_white">
    <color rgba="0.866666666666667 0.866666666666667 0.890196078431373 1"/>
  </material>

  <!-- Indy7 (link & joint) -->
  <link name="link0">
    <visual>
      <origin rpy="0 0 0" xyz="0 0 0"/>
      <geometry>
        <mesh filename="package://indy7_visualization/meshes/stl/Indy7_0.stl"/>
      </geometry>
      <material name="metal_grey"/>
    </visual>
    <collision>
      <origin rpy="0 0 0" xyz="0 0 0.0385"/>
      <geometry>
        <cylinder radius="0.11" length="0.077"/>
      </geometry>
    </collision>
    <inertial>
      <origin rpy="0 0 0" xyz="0.00131966 -0.00000218 0.03212832"/>
      <mass value="1.67030785"/>
      <inertia ixx="+0.00661309" ixy="+0.00000183" ixz="+0.00002695" iyy="+0.00644765" iyz="-0.00000027" izz="+0.00792090"/>
    </inertial>
  </link>
  <link name="link1">
    <visual>
      <origin rpy="0 0 0" xyz="0 0 0"/>
      <geometry>
        <mesh filename="package://indy7_visualization/meshes/stl/Indy7_1.stl"/>
      </geometry>
      <material name="metal_grey"/>
    </visual>
    <collision>
      <origin rpy="0 0 0" xyz="0 0 0.075"/>
      <geometry>
        <cylinder radius="0.075" length="0.15"/>
      </geometry>
    </collision>
    <collision>
      <origin rpy="1.5707963267948966 0 0" xyz="0 0. 0.225"/>
      <geometry>
        <capsule radius="0.075" length="0.09"/>
      </geometry>
    </collision>
    <inertial>
      <origin rpy="0 0 0" xyz="-0.00023749 -0.04310313 0.13245396"/>
      <mass value="11.44444535"/>
      <inertia ixx="+0.35065005" ixy="+0.00011931" ixz="-0.00037553" iyy="+0.30479800" iyz="-0.10984447" izz="+0.06003147"/>
    </inertial>
  </link>
  <link name="link2">
    <visual>
      <origin rpy="0 0 0" xyz="0 0 0"/>
      <geometry>
        <mesh filename="package://indy7_visualization/meshes/stl/Indy7_2.stl"/>
      </geometry>
      <material name="metal_grey"/>
    </visual>
    <collision>
      <origin rpy="0 1.5707963267948966 0" xyz="-0.21 0 0.075"/>
      <geometry>
        <capsule radius="0.075" length="0.3"/>
      </geometry>
    </collision>
    <inertial>
      <origin rpy="0 0 0" xyz="-0.29477536 -0.00002361 0.04762554"/>
      <mass value="5.84766553"/>
      <inertia ixx="+0.03599743" ixy="-0.00004693" ixz="-0.05240346" iyy="+0.72293306" iyz="+0.00000176" izz="+0.70024119"/>
    </inertial>
  </link>
  <link name="link3">
    <visual>
      <origin rpy="0 0 0" xyz="0 0 0"/>
      <geometry>
        <mesh filename="package://indy7_visualization/meshes/stl/Indy7_3.stl"/>
      </geometry>
      <material name="metal_grey"/>
    </visual>
    <collision>
      <origin rpy="0 0 0" xyz="0 0 0"/>
      <geometry>
        <cylinder radius="0.05" length="0.05"/>
      </geometry>
    </collision>
    <collision>
      <origin rpy="0 1.5707963267948966 0" xyz="-0.175 0 -0.075"/>
      <geometry>
        <capsule radius="0.05" length="0.22"/>
      </geometry>
    </collision>
    <inertial>
      <origin rpy="0 0 0" xyz="-0.16804016 0.00021421 -0.07000383"/>
      <mass value="2.68206064"/>
      <inertia ixx="+0.01617210" ixy="-0.00011817" ixz="+0.03341882" iyy="+0.11364055" iyz="-0.00004371" izz="+0.10022522"/>
    </inertial>
  </link>
  <link name="link4">
    <visual>
      <origin rpy="0 0 0" xyz="0 0 0"/>
      <geometry>
        <mesh filename="package://indy7_visualization/meshes/stl/Indy7_4.stl"/>
      </geometry>
      <material name="metal_grey"/>
    </visual>
    <collision>
      <origin rpy="1.5707963267948966 0 0" xyz="0 -0.065 0.08"/>
      <geometry>
        <cylinder radius="0.05" length="0.13"/>
      </geometry>
    </collision>
    <inertial>
      <origin rpy="0 0 0" xyz="-0.00026847 -0.07098440 0.07649128"/>
      <mass value="2.12987371"/>
      <inertia ixx="+0.02798891" ixy="+0.00003893" ixz="-0.00004768" iyy="+0.01443076" iyz="-0.01266296" izz="+0.01496211"/>
    </inertial>
  </link>
  <link name="link5">
    <visual>
      <origin rpy="0 0 0" xyz="0 0 0"/>
      <geometry>
        <mesh filename="package://indy7_visualization/meshes/stl/Indy7_5.stl"/>
      </geometry>
      <material name="metal_grey"/>
    </visual>
    <collision>
      <origin rpy="0 1.5707963267948966 0" xyz="-0.06 0 0.07"/>
      <geometry>
        <cylinder radius="0.05" length="0.21"/>
      </geometry>
    </collision>
    <inertial>
      <origin rpy="0 0 0" xyz="-0.09796232 -0.00023114 0.06445892"/>
      <mass value="2.22412271"/>
      <inertia ixx="+0.01105297" ixy="+0.00005517" ixz="-0.01481977" iyy="+0.03698291" iyz="-0.00003740" izz="+0.02754795"/>
    </inertial>
  </link>
  <link name="link6">
    <visual>
      <origin rpy="0 0 0" xyz="0 0 0"/>
      <geometry>
        <mesh filename="package://indy7_visualization/meshes/stl/Indy7_6.stl"/>
      </geometry>
      <material name="metal_grey"/>
    </visual>
    <collision>
      <origin rpy="0 0 0" xyz="0 0 0.03"/>
      <geometry>
        <cylinder radius="0.05" length="0.06"/>
      </geometry>
    </collision>
    <inertial>
      <origin rpy="0 0 0" xyz="0.00008147 -0.00046556 0.03079097"/>
      <mass value="0.38254932"/>
      <inertia ixx="+0.00078982" ixy="-0.00000034" ixz="+0.00000083" iyy="+0.00079764" iyz="-0.00000508" izz="+0.00058319"/>
    </inertial>
  </link>
  <link name="tcp"/>

  <joint name="joint0" type="revolute">
    <parent link="link0"/>
    <child link="link1"/>
    <origin rpy="0 0 0" xyz="0 0 0.0775"/>
    <axis xyz="0 0 1"/>
    <limit effort="431.97" lower="-3.0543261909900763" upper="3.0543261909900763" velocity="159."/>
  </joint>
  <joint name="joint1" type="revolute">
    <parent link="link1"/>
    <child link="link2"/>
    <origin rpy="1.5707963267948966 1.5707963267948966 0" xyz="0 -0.10900000 0.22200000"/>
    <axis xyz="0 0 1"/>
    <limit effort="431.97" lower="-3.0543261909900763" upper="3.0543261909900763" velocity="159."/>
  </joint>
  <joint name="joint2" type="revolute">
    <parent link="link2"/>
    <child link="link3"/>
    <origin rpy="0 0 0" xyz="-0.45000000 +0.00000000 -0.03050000"/>
    <axis xyz="0 0 1"/>
    <limit effort="197.23" lower="-3.0543261909900763" upper="3.0543261909900763" velocity="189."/>
  </joint>
  <joint name="joint3" type="revolute">
    <parent link="link3"/>
    <child link="link4"/>
    <origin rpy="-1.5707963267948966 0 1.5707963267948966" xyz="-0.26700000 +0.00000000 -0.07500000"/>
    <axis xyz="0 0 1"/>
    <limit effort="79.79" lower="-3.0543261909900763" upper="3.0543261909900763" velocity="189."/>
  </joint>
  <joint name="joint4" type="revolute">
    <parent link="link4"/>
    <child link="link5"/>
    <origin rpy="1.5707963267948966 1.5707963267948966 0" xyz="+0.00000000 -0.11400000 +0.08300000"/>
    <axis xyz="0 0 1"/>
    <limit effort="79.79" lower="-3.0543261909900763" upper="3.0543261909900763" velocity="189."/>
  </joint>
  <joint name="joint5" type="revolute">
    <parent link="link5"/>
    <child link="link6"/>
    <origin rpy="-1.5707963267948966 0 1.5707963267948966" xyz="-0.16800000 +0.00000000 +0.06900000"/>
    <axis xyz="0 0 1"/>
    <limit effort="79.79" lower="-3.752457891787808" upper="3.752457891787808" velocity="189."/>
  </joint>
  <joint name="tcp" type="fixed">
    <parent link="link6"/>
    <child link="tcp"/>
    <origin rpy="0 0 0" xyz="0 0 0.06"/>
  </joint>

  <!-- Allegro hand right (link & joint) -->
  <link name="allegro_base_link">
    <visual>
      <geometry>
        <mesh filename="package://allegro_hand_visualization/meshes/base_link.STL"/>
      </geometry>
      <origin rpy="0 0 0" xyz="0 0 0 "/>
      <material name="black">
        <color rgba="0.2 0.2 0.2 1"/>
      </material>
    </visual>
    <collision>
      <origin rpy="0 0 0" xyz="-0.009300 0 -0.0475"/>
      <geometry>
        <box size="0.0408 0.1130 0.095"/>
      </geometry>
    </collision>
  </link>
  <joint name="allegro_base_joint" type="fixed">
    <parent link="tcp"/>
    <child link="allegro_base_link"/>
    <origin rpy="0 0 0" xyz="0 0 0.095"/>
  </joint>
  <!-- FINGERS -->
  <link name="allegro_link_0_0">
    <visual>
      <geometry>
        <mesh filename="package://allegro_hand_visualization/meshes/link_0.0.STL"/>
      </geometry>
      <material name="black"/>
    </visual>
    <collision>
      <geometry>
        <box size="0.0196 0.0275 0.0164"/>
      </geometry>
      <origin rpy="0 0 0" xyz="0 0 0.0082"/>
    </collision>
  </link>
  <joint name="allegro_joint_0_0" type="revolute">
    <axis xyz="0 0 1"/>
    <limit effort="0" lower="-0.47" upper="0.47" velocity="0"/>
    <parent link="allegro_base_link"/>
    <child link="allegro_link_0_0"/>
    <origin rpy="-0.08726646255 0 0" xyz="0 0.0435 -0.001542"/>
  </joint>
  <link name="allegro_link_1_0">
    <visual>
      <geometry>
        <mesh filename="package://allegro_hand_visualization/meshes/link_1.0.STL"/>
      </geometry>
      <material name="black"/>
    </visual>
    <collision>
      <geometry>
        <box size="0.0196 0.0275 0.054"/>
      </geometry>
      <origin rpy="0 0 0" xyz="0 0 0.027"/>
    </collision>
  </link>
  <joint name="allegro_joint_1_0" type="revolute">
    <limit effort="0" lower="-0.196" upper="1.61" velocity="0"/>
    <axis xyz="0 1 0"/>
    <parent link="allegro_link_0_0"/>
    <child link="allegro_link_1_0"/>
    <origin xyz="0 0 0.0164"/>
  </joint>
  <link name="allegro_link_2_0">
    <visual>
      <geometry>
        <mesh filename="package://allegro_hand_visualization/meshes/link_2.0.STL"/>
      </geometry>
      <material name="black"/>
    </visual>
    <collision>
      <geometry>
        <box size="0.0196 0.0275 0.0384"/>
      </geometry>
      <origin rpy="0 0 0" xyz="0 0 0.0192"/>
    </collision>
  </link>
  <joint name="allegro_joint_2_0" type="revolute">
    <axis xyz="0 1 0"/>
    <limit effort="0" lower="-0.174" upper="1.709" velocity="0"/>
    <parent link="allegro_link_1_0"/>
    <child link="allegro_link_2_0"/>
    <origin xyz="0 0 0.054"/>
  </joint>
  <link name="allegro_link_3_0">
    <visual>
      <geometry>
        <mesh filename="package://allegro_hand_visualization/meshes/link_3.0.STL"/>
      </geometry>
      <material name="black"/>
    </visual>
    <collision>
      <geometry>
        <box size="0.0196 0.0275 0.0267"/>
      </geometry>
      <origin rpy="0 0 0" xyz="0 0 0.01335"/>
    </collision>
  </link>
  <joint name="allegro_joint_3_0" type="revolute">
    <axis xyz="0 1 0"/>
    <limit effort="0" lower="-0.227" upper="1.618" velocity="0"/>
    <parent link="allegro_link_2_0"/>
    <child link="allegro_link_3_0"/>
    <origin xyz="0 0 0.0384"/>
  </joint>
  <link name="allegro_link_3_0_tip">
    <visual>
      <geometry>
        <mesh filename="package://allegro_hand_visualization/meshes/link_3.0_tip.STL"/>
      </geometry>
      <material name="white">
        <color rgba=".9 .9 .9 1"/>
      </material>
    </visual>
    <collision>
      <geometry>
        <sphere radius="0.012"/>
      </geometry>
    </collision>
  </link>
  <joint name="allegro_joint_3_0_tip" type="fixed">
    <parent link="allegro_link_3_0"/>
    <child link="allegro_link_3_0_tip"/>
    <origin rpy="0 0 0" xyz="0 0 0.0267"/>
  </joint>
  <link name="allegro_link_4_0">
    <visual>
      <geometry>
        <mesh filename="package://allegro_hand_visualization/meshes/link_0.0.STL"/>
      </geometry>
      <material name="black"/>
    </visual>
    <collision>
      <geometry>
        <box size="0.0196 0.0275 0.0164"/>
      </geometry>
      <origin rpy="0 0 0" xyz="0 0 0.0082"/>
    </collision>
  </link>
  <joint name="allegro_joint_4_0" type="revolute">
    <axis xyz="0 0 1"/>
    <limit effort="0" lower="-0.47" upper="0.47" velocity="0"/>
    <parent link="allegro_base_link"/>
    <child link="allegro_link_4_0"/>
    <origin rpy="0.0 0 0" xyz="0 0 0.0007"/>
  </joint>
  <link name="allegro_link_5_0">
    <visual>
      <geometry>
        <mesh filename="package://allegro_hand_visualization/meshes/link_1.0.STL"/>
      </geometry>
      <material name="black"/>
    </visual>
    <collision>
      <geometry>
        <box size="0.0196 0.0275 0.054"/>
      </geometry>
      <origin rpy="0 0 0" xyz="0 0 0.027"/>
    </collision>
  </link>
  <joint name="allegro_joint_5_0" type="revolute">
    <limit effort="0" lower="-0.196" upper="1.61" velocity="0"/>
    <axis xyz="0 1 0"/>
    <parent link="allegro_link_4_0"/>
    <child link="allegro_link_5_0"/>
    <origin xyz="0 0 0.0164"/>
  </joint>
  <link name="allegro_link_6_0">
    <visual>
      <geometry>
        <mesh filename="package://allegro_hand_visualization/meshes/link_2.0.STL"/>
      </geometry>
      <material name="black"/>
    </visual>
    <collision>
      <geometry>
        <box size="0.0196 0.0275 0.0384"/>
      </geometry>
      <origin rpy="0 0 0" xyz="0 0 0.0192"/>
    </collision>
  </link>
  <joint name="allegro_joint_6_0" type="revolute">
    <axis xyz="0 1 0"/>
    <limit effort="0" lower="-0.174" upper="1.709" velocity="0"/>
    <parent link="allegro_link_5_0"/>
    <child link="allegro_link_6_0"/>
    <origin xyz="0 0 0.054"/>
  </joint>
  <link name="allegro_link_7_0">
    <visual>
      <geometry>
        <mesh filename="package://allegro_hand_visualization/meshes/link_3.0.STL"/>
      </geometry>
      <material name="black"/>
    </visual>
    <collision>
      <geometry>
        <box size="0.0196 0.0275 0.0267"/>
      </geometry>
      <origin rpy="0 0 0" xyz="0 0 0.01335"/>
    </collision>
  </link>
  <joint name="allegro_joint_7_0" type="revolute">
    <axis xyz="0 1 0"/>
    <limit effort="0" lower="-0.227" upper="1.618" velocity="0"/>
    <parent link="allegro_link_6_0"/>
    <child link="allegro_link_7_0"/>
    <origin xyz="0 0 0.0384"/>
  </joint>
  <link name="allegro_link_7_0_tip">
    <visual>
      <geometry>
        <mesh filename="package://allegro_hand_visualization/meshes/link_3.0_tip.STL"/>
      </geometry>
      <material name="white">
        <color rgba=".9 .9 .9 1"/>
      </material>
    </visual>
    <collision>
      <geometry>
        <sphere radius="0.012"/>
      </geometry>
    </collision>
  </link>
  <joint name="allegro_joint_7_0_tip" type="fixed">
    <parent link="allegro_link_7_0"/>
    <child link="allegro_link_7_0_tip"/>
    <origin rpy="0 0 0" xyz="0 0 0.0267"/>
  </joint>
  <link name="allegro_link_8_0">
    <visual>
      <geometry>
        <mesh filename="package://allegro_hand_visualization/meshes/link_0.0.STL"/>
      </geometry>
      <material name="black"/>
    </visual>
    <collision>
      <geometry>
        <box size="0.0196 0.0275 0.0164"/>
      </geometry>
      <origin rpy="0 0 0" xyz="0 0 0.0082"/>
    </collision>
  </link>
  <joint name="allegro_joint_8_0" type="revolute">
    <axis xyz="0 0 1"/>
    <limit effort="0" lower="-0.47" upper="0.47" velocity="0"/>
    <parent link="allegro_base_link"/>
    <child link="allegro_link_8_0"/>
    <origin rpy="0.08726646255 0 0" xyz="0 -0.0435 -0.001542"/>
  </joint>
  <link name="allegro_link_9_0">
    <visual>
      <geometry>
        <mesh filename="package://allegro_hand_visualization/meshes/link_1.0.STL"/>
      </geometry>
      <material name="black"/>
    </visual>
    <collision>
      <geometry>
        <box size="0.0196 0.0275 0.054"/>
      </geometry>
      <origin rpy="0 0 0" xyz="0 0 0.027"/>
    </collision>
  </link>
  <joint name="allegro_joint_9_0" type="revolute">
    <limit effort="0" lower="-0.196" upper="1.61" velocity="0"/>
    <axis xyz="0 1 0"/>
    <parent link="allegro_link_8_0"/>
    <child link="allegro_link_9_0"/>
    <origin xyz="0 0 0.0164"/>
  </joint>
  <link name="allegro_link_10_0">
    <visual>
      <geometry>
        <mesh filename="package://allegro_hand_visualization/meshes/link_2.0.STL"/>
      </geometry>
      <material name="black"/>
    </visual>
    <collision>
      <geometry>
        <box size="0.0196 0.0275 0.0384"/>
      </geometry>
      <origin rpy="0 0 0" xyz="0 0 0.0192"/>
    </collision>
  </link>
  <joint name="allegro_joint_10_0" type="revolute">
    <axis xyz="0 1 0"/>
    <limit effort="0" lower="-0.174" upper="1.709" velocity="0"/>
    <parent link="allegro_link_9_0"/>
    <child link="allegro_link_10_0"/>
    <origin xyz="0 0 0.054"/>
  </joint>
  <link name="allegro_link_11_0">
    <visual>
      <geometry>
        <mesh filename="package://allegro_hand_visualization/meshes/link_3.0.STL"/>
      </geometry>
      <material name="black"/>
    </visual>
    <collision>
      <geometry>
        <box size="0.0196 0.0275 0.0267"/>
      </geometry>
      <origin rpy="0 0 0" xyz="0 0 0.01335"/>
    </collision>
  </link>
  <joint name="allegro_joint_11_0" type="revolute">
    <axis xyz="0 1 0"/>
    <limit effort="0" lower="-0.227" upper="1.618" velocity="0"/>
    <parent link="allegro_link_10_0"/>
    <child link="allegro_link_11_0"/>
    <origin xyz="0 0 0.0384"/>
  </joint>
  <link name="allegro_link_11_0_tip">
    <visual>
      <geometry>
        <mesh filename="package://allegro_hand_visualization/meshes/link_3.0_tip.STL"/>
      </geometry>
      <material name="white">
        <color rgba=".9 .9 .9 1"/>
      </material>
    </visual>
    <collision>
      <geometry>
        <sphere radius="0.012"/>
      </geometry>
    </collision>
  </link>
  <joint name="allegro_joint_11_0_tip" type="fixed">
    <parent link="allegro_link_11_0"/>
    <child link="allegro_link_11_0_tip"/>
    <origin rpy="0 0 0" xyz="0 0 0.0267"/>
  </joint>
  <!-- THUMB -->
  <link name="allegro_link_12_0">
    <visual>
      <geometry>
        <mesh filename="package://allegro_hand_visualization/meshes/link_12.0_right.STL"/>
      </geometry>
      <material name="black">
        <color rgba=".2 .2 .2 1"/>
      </material>
    </visual>
    <collision>
      <geometry>
        <box size="0.0358 0.034 0.0455"/>
      </geometry>
      <origin rpy="0 0 0" xyz="-0.0179 0.009 0.0145"/>
    </collision>
  </link>
  <joint name="allegro_joint_12_0" type="revolute">
    <axis xyz="-1 0 0"/>
    <limit effort="0" lower="0.263" upper="1.396" velocity="0"/>
    <parent link="allegro_base_link"/>
    <child link="allegro_link_12_0"/>
    <origin rpy="0 -1.65806278845 -1.5707963259" xyz="-0.0182 0.019333 -0.045987"/>
  </joint>
  <link name="allegro_link_13_0">
    <visual>
      <geometry>
        <mesh filename="package://allegro_hand_visualization/meshes/link_13.0.STL"/>
      </geometry>
      <material name="black">
        <color rgba=".2 .2 .2 1"/>
      </material>
    </visual>
    <collision>
      <geometry>
        <box size="0.0196 0.0275 0.0177"/>
      </geometry>
      <origin rpy="0 0 0" xyz="0 0 0.00885"/>
    </collision>
  </link>
  <joint name="allegro_joint_13_0" type="revolute">
    <axis xyz="0 0 1"/>
    <limit effort="0" lower="-0.105" upper="1.163" velocity="0"/>
    <parent link="allegro_link_12_0"/>
    <child link="allegro_link_13_0"/>
    <origin xyz="-0.027 0.005 0.0399"/>
  </joint>
  <link name="allegro_link_14_0">
    <visual>
      <geometry>
        <mesh filename="package://allegro_hand_visualization/meshes/link_14.0.STL"/>
      </geometry>
      <material name="black">
		  	</material>
    </visual>
    <collision>
      <geometry>
        <box size="0.0196 0.0275 0.0514"/>
      </geometry>
      <origin rpy="0 0 0" xyz="0 0 0.0257"/>
    </collision>
  </link>
  <joint name="allegro_joint_14_0" type="revolute">
    <axis xyz="0 1 0"/>
    <limit effort="0" lower="-0.189" upper="1.644" velocity="0"/>
    <parent link="allegro_link_13_0"/>
    <child link="allegro_link_14_0"/>
    <origin xyz="0 0 0.0177"/>
  </joint>
  <link name="allegro_link_15_0">
    <visual>
      <geometry>
        <mesh filename="package://allegro_hand_visualization/meshes/link_15.0.STL"/>
      </geometry>
      <material name="black">
    	</material>
    </visual>
    <collision>
      <geometry>
        <box size="0.0196 0.0275 0.0423"/>
      </geometry>
      <origin rpy="0 0 0" xyz="0 0 0.02115"/>
    </collision>
  </link>
  <joint name="allegro_joint_15_0" type="revolute">
    <axis xyz="0 1 0"/>
    <limit effort="0" lower="-0.162" upper="1.719" velocity="0"/>
    <parent link="allegro_link_14_0"/>
    <child link="allegro_link_15_0"/>
    <origin xyz="0 0 0.0514"/>
  </joint>
  <link name="allegro_link_15_0_tip">
    <visual>
      <geometry>
        <mesh filename="package://allegro_hand_visualization/meshes/link_15.0_tip.STL"/>
      </geometry>
      <material name="white">
        <color rgba=".9 .9 .9 1"/>
      </material>
    </visual>
    <collision>
      <geometry>
        <sphere radius="0.012"/>
      </geometry>
      <origin rpy="0 0 0" xyz="0 0 0"/>
    </collision>
  </link>
  <joint name="allegro_joint_15_0_tip" type="fixed">
    <parent link="allegro_link_15_0"/>
    <child link="allegro_link_15_0_tip"/>
    <origin rpy="0 0 0" xyz="0 0 0.0423"/>
  </joint>

</robot>
